<?xml version="1.0" ?>
<!-- =================================================================================== -->
<!-- |    This document was autogenerated by xacro from ./src/skootr_description/urdf/skootr.xacro | -->
<!-- |    EDITING THIS FILE BY HAND IS NOT RECOMMENDED                                 | -->
<!-- =================================================================================== -->
<robot name="skootr">
  <!-- Declare colors -->
  <material name="skootr_blue">
    <color rgba="0.231 0.380 0.706 1.0"/>
  </material>
  <material name="skootr_yellow">
    <color rgba="0.980 0.714 0.004 1.0"/>
  </material>
  <material name="skootr_silver">
    <color rgba="0.9176 0.9176 0.9176 1.0"/>
  </material>
  <material name="servo_blue">
    <color rgba="0.043 0.216 0.404 1.0"/>
  </material>
  <material name="horn_purple">
    <color rgba="0.490 0.086 0.557 1.0"/>
  </material>
  <link name="ball_root">
    <origin rpy="0.0 0.0 0.0" xyz="0.0 0.0 0.0"/>
  </link>
  <link name="ball_connector">
    <visual>
      <geometry>
        <mesh filename="package:///meshes/frame/hemisphere_connector.stl" scale="0.001 0.001 0.001"/>
      </geometry>
    </visual>
    <collision>
      <geometry>
        <mesh filename="package:///meshes/frame/hemisphere_connector.stl" scale="0.001 0.001 0.001"/>
      </geometry>
    </collision>
  </link>
  <!-- joining ball_connector to dummy link -->
  <joint name="root_to_connector" type="fixed">
    <origin rpy="1.5707963267948966 0 0" xyz="0.0 0.0 0.0195"/>
    <parent link="ball_root"/>
    <child link="ball_connector"/>
  </joint>
  <!-- top hemisphere -->
  <link name="hemisphere_top">
    <visual>
      <geometry>
        <mesh filename="package:///meshes/frame/hemisphere.stl" scale="0.001 0.001 0.001"/>
      </geometry>
      <material name="skootr_silver"/>
    </visual>
    <collision>
      <geometry>
        <mesh filename="package:///meshes/frame/hemisphere.stl" scale="0.001 0.001 0.001"/>
      </geometry>
    </collision>
  </link>
  <link name="hemisphere_bottom">
    <visual>
      <geometry>
        <mesh filename="package:///meshes/frame/hemisphere.stl" scale="0.001 0.001 0.001"/>
      </geometry>
      <material name="skootr_silver"/>
    </visual>
    <collision>
      <geometry>
        <mesh filename="package:///meshes/frame/hemisphere.stl" scale="0.001 0.001 0.001"/>
      </geometry>
    </collision>
  </link>
  <joint name="connector_to_top" type="fixed">
    <parent link="ball_connector"/>
    <child link="hemisphere_top"/>
    <origin rpy="0 0 0" xyz="0 -0.0195 0"/>
  </joint>
  <joint name="connector_to_bottom" type="fixed">
    <parent link="ball_connector"/>
    <child link="hemisphere_bottom"/>
    <origin rpy="3.14159265 0 0" xyz="0 -0.0195 0"/>
  </joint>
  <!-- ring constraint -->
  <link name="first_ring" type="fixed">
    <visual>
      <geometry>
        <mesh filename="package:///meshes/frame/ringconstraint.stl" scale="0.001 0.001 0.001"/>
      </geometry>
      <material name="skootr_yellow"/>
    </visual>
    <collision>
      <geometry>
        <mesh filename="package:///meshes/frame/ringconstraint.stl" scale="0.001 0.001 0.001"/>
      </geometry>
    </collision>
  </link>
  <link name="first_constraint_connector" type="fixed">
    <visual>
      <geometry>
        <mesh filename="package:///meshes/frame/ringconstraint_connector.stl" scale="0.001 0.001 0.001"/>
      </geometry>
      <material name="skootr_yellow"/>
    </visual>
    <collision>
      <geometry>
        <mesh filename="package:///meshes/frame/ringconstraint_connector.stl" scale="0.001 0.001 0.001"/>
      </geometry>
    </collision>
  </link>
  <link name="first_triconstraint" type="fixed">
    <visual>
      <geometry>
        <mesh filename="package:///meshes/frame/triconstraint.stl" scale="0.001 0.001 0.001"/>
      </geometry>
      <material name="skootr_blue"/>
    </visual>
    <collision>
      <geometry>
        <mesh filename="package:///meshes/frame/triconstraint.stl" scale="0.001 0.001 0.001"/>
      </geometry>
    </collision>
  </link>
  <link name="second_ring" type="fixed">
    <visual>
      <geometry>
        <mesh filename="package:///meshes/frame/ringconstraint.stl" scale="0.001 0.001 0.001"/>
      </geometry>
      <material name="skootr_yellow"/>
    </visual>
    <collision>
      <geometry>
        <mesh filename="package:///meshes/frame/ringconstraint.stl" scale="0.001 0.001 0.001"/>
      </geometry>
    </collision>
  </link>
  <link name="second_constraint_connector" type="fixed">
    <visual>
      <geometry>
        <mesh filename="package:///meshes/frame/ringconstraint_connector.stl" scale="0.001 0.001 0.001"/>
      </geometry>
      <material name="skootr_yellow"/>
    </visual>
    <collision>
      <geometry>
        <mesh filename="package:///meshes/frame/ringconstraint_connector.stl" scale="0.001 0.001 0.001"/>
      </geometry>
    </collision>
  </link>
  <link name="second_triconstraint" type="fixed">
    <visual>
      <geometry>
        <mesh filename="package:///meshes/frame/triconstraint.stl" scale="0.001 0.001 0.001"/>
      </geometry>
      <material name="skootr_blue"/>
    </visual>
    <collision>
      <geometry>
        <mesh filename="package:///meshes/frame/triconstraint.stl" scale="0.001 0.001 0.001"/>
      </geometry>
    </collision>
  </link>
  <link name="third_ring" type="fixed">
    <visual>
      <geometry>
        <mesh filename="package:///meshes/frame/ringconstraint.stl" scale="0.001 0.001 0.001"/>
      </geometry>
      <material name="skootr_yellow"/>
    </visual>
    <collision>
      <geometry>
        <mesh filename="package:///meshes/frame/ringconstraint.stl" scale="0.001 0.001 0.001"/>
      </geometry>
    </collision>
  </link>
  <link name="third_constraint_connector" type="fixed">
    <visual>
      <geometry>
        <mesh filename="package:///meshes/frame/ringconstraint_connector.stl" scale="0.001 0.001 0.001"/>
      </geometry>
      <material name="skootr_yellow"/>
    </visual>
    <collision>
      <geometry>
        <mesh filename="package:///meshes/frame/ringconstraint_connector.stl" scale="0.001 0.001 0.001"/>
      </geometry>
    </collision>
  </link>
  <link name="third_triconstraint" type="fixed">
    <visual>
      <geometry>
        <mesh filename="package:///meshes/frame/triconstraint.stl" scale="0.001 0.001 0.001"/>
      </geometry>
      <material name="skootr_blue"/>
    </visual>
    <collision>
      <geometry>
        <mesh filename="package:///meshes/frame/triconstraint.stl" scale="0.001 0.001 0.001"/>
      </geometry>
    </collision>
  </link>
  <link name="triconstraint_hub" type="fixed">
    <visual>
      <geometry>
        <mesh filename="package:///meshes/frame/triconstraint_hub.stl" scale="0.001 0.001 0.001"/>
      </geometry>
      <material name="skootr_blue"/>
    </visual>
    <collision>
      <geometry>
        <mesh filename="package:///meshes/frame/triconstraint_hub.stl" scale="0.001 0.001 0.001"/>
      </geometry>
    </collision>
  </link>
  <joint name="first_ring_to_ball" type="fixed">
    <origin rpy="0.0 0.0 0.0" xyz="0.0 0.0 -0.00975"/>
    <parent link="ball_root"/>
    <child link="first_ring"/>
  </joint>
  <joint name="first_ring_to_connector" type="fixed">
    <origin rpy="0.0 0.0 0.0" xyz="0.0 0.0 -0.00975"/>
    <parent link="ball_root"/>
    <child link="first_constraint_connector"/>
  </joint>
  <joint name="first_triconstraint_to_connector" type="fixed">
    <origin rpy="0.0 0.0 0.5235987755982988" xyz="0.0 0.0 0.00975"/>
    <parent link="first_ring"/>
    <child link="first_triconstraint"/>
  </joint>
  <joint name="second_ring_to_ball" type="fixed">
    <origin rpy="0.0 0.0 2.0943951023931953" xyz="0.0 0.0 -0.00975"/>
    <parent link="ball_root"/>
    <child link="second_ring"/>
  </joint>
  <joint name="second_ring_to_connector" type="fixed">
    <origin rpy="0.0 0.0 2.0943951023931953" xyz="0.0 0.0 -0.00975"/>
    <parent link="ball_root"/>
    <child link="second_constraint_connector"/>
  </joint>
  <joint name="second_triconstraint_to_connector" type="fixed">
    <origin rpy="0.0 0.0 0.5235987755982988" xyz="0.0 0.0 0.00975"/>
    <parent link="second_ring"/>
    <child link="second_triconstraint"/>
  </joint>
  <joint name="third_ring_to_ball" type="fixed">
    <origin rpy="0.0 0.0 4.1887902047863905" xyz="0.0 0.0 -0.00975"/>
    <parent link="ball_root"/>
    <child link="third_ring"/>
  </joint>
  <joint name="third_ring_to_connector" type="fixed">
    <origin rpy="0.0 0.0 4.1887902047863905" xyz="0.0 0.0 -0.00975"/>
    <parent link="ball_root"/>
    <child link="third_constraint_connector"/>
  </joint>
  <joint name="third_triconstraint_to_connector" type="fixed">
    <origin rpy="0.0 0.0 0.5235987755982988" xyz="0.0 0.0 0.00975"/>
    <parent link="third_ring"/>
    <child link="third_triconstraint"/>
  </joint>
  <joint name="triconstraints_to_hub" type="fixed">
    <origin rpy="0.0 0.0 0.5235987755982988" xyz="0.0 0.0 0.0"/>
    <parent link="ball_root"/>
    <child link="triconstraint_hub"/>
  </joint>
  <link name="metal_bearing" type="fixed">
    <visual>
      <geometry>
        <mesh filename="package:///meshes/non_printed/metal_bearing.stl" scale="0.001 0.001 0.001"/>
      </geometry>
      <material name="skootr_silver"/>
    </visual>
    <collision>
      <geometry>
        <mesh filename="package:///meshes/non_printed/metal_bearing.stl" scale="0.001 0.001 0.001"/>
      </geometry>
    </collision>
  </link>
  <link name="first_metal_bearing" type="fixed">
    <visual>
      <geometry>
        <mesh filename="package:///meshes/non_printed/metal_bearing.stl" scale="0.001 0.001 0.001"/>
      </geometry>
      <material name="skootr_silver"/>
    </visual>
    <collision>
      <geometry>
        <mesh filename="package:///meshes/non_printed/metal_bearing.stl" scale="0.001 0.001 0.001"/>
      </geometry>
    </collision>
  </link>
  <link name="second_metal_bearing" type="fixed">
    <visual>
      <geometry>
        <mesh filename="package:///meshes/non_printed/metal_bearing.stl" scale="0.001 0.001 0.001"/>
      </geometry>
      <material name="skootr_silver"/>
    </visual>
    <collision>
      <geometry>
        <mesh filename="package:///meshes/non_printed/metal_bearing.stl" scale="0.001 0.001 0.001"/>
      </geometry>
    </collision>
  </link>
  <link name="third_metal_bearing" type="fixed">
    <visual>
      <geometry>
        <mesh filename="package:///meshes/non_printed/metal_bearing.stl" scale="0.001 0.001 0.001"/>
      </geometry>
      <material name="skootr_silver"/>
    </visual>
    <collision>
      <geometry>
        <mesh filename="package:///meshes/non_printed/metal_bearing.stl" scale="0.001 0.001 0.001"/>
      </geometry>
    </collision>
  </link>
  <link name="servo_hub_bottom" type="fixed">
    <visual>
      <geometry>
        <mesh filename="package:///meshes/frame/servo_hub_bottom.stl" scale="0.001 0.001 0.001"/>
      </geometry>
      <material name="skootr_blue"/>
    </visual>
    <collision>
      <geometry>
        <mesh filename="package:///meshes/frame/servo_hub_bottom.stl" scale="0.001 0.001 0.001"/>
      </geometry>
    </collision>
  </link>
  <joint name="hub_to_bearing" type="fixed">
    <origin rpy="-1.5707963267948966 0.0 0.0" xyz="0.0 0.0 0.138835"/>
    <parent link="triconstraint_hub"/>
    <child link="metal_bearing"/>
  </joint>
  <joint name="first_triconstraint_to_bearing" type="fixed">
    <origin rpy="0.20 0.0 -1.5707963267948966" xyz="-0.1322 0.0 -0.0274574"/>
    <parent link="first_triconstraint"/>
    <child link="first_metal_bearing"/>
  </joint>
  <joint name="second_triconstraint_to_bearing" type="fixed">
    <origin rpy="0.20 0.0 -1.5707963267948966" xyz="-0.1322 0.0 -0.0274574"/>
    <parent link="second_triconstraint"/>
    <child link="second_metal_bearing"/>
  </joint>
  <joint name="third_triconstraint_to_bearing" type="fixed">
    <origin rpy="0.20 0.0 -1.5707963267948966" xyz="-0.1322 0.0 -0.0274574"/>
    <parent link="third_triconstraint"/>
    <child link="third_metal_bearing"/>
  </joint>
  <joint name="triconstraint_to_bottomhubs" type="fixed">
    <origin rpy="0.0 0.0 0.0" xyz="0.0 0.0 0.103912"/>
    <parent link="first_triconstraint"/>
    <child link="servo_hub_bottom"/>
  </joint>
  <!-- Servo -->
  <link name="first_servo">
    <visual>
      <geometry>
        <mesh filename="package:///meshes/non_printed/60_kg_servo.stl" scale="0.001 0.001 0.001"/>
      </geometry>
      <material name="servo_blue"/>
    </visual>
    <collision>
      <geometry>
        <mesh filename="package:///meshes/non_printed/60_kg_servo.stl" scale="0.001 0.001 0.001"/>
      </geometry>
    </collision>
  </link>
  <link name="second_servo">
    <visual>
      <geometry>
        <mesh filename="package:///meshes/non_printed/60_kg_servo.stl" scale="0.001 0.001 0.001"/>
      </geometry>
      <material name="servo_blue"/>
    </visual>
    <collision>
      <geometry>
        <mesh filename="package:///meshes/non_printed/60_kg_servo.stl" scale="0.001 0.001 0.001"/>
      </geometry>
    </collision>
  </link>
  <link name="third_servo">
    <visual>
      <geometry>
        <mesh filename="package:///meshes/non_printed/60_kg_servo.stl" scale="0.001 0.001 0.001"/>
      </geometry>
      <material name="servo_blue"/>
    </visual>
    <collision>
      <geometry>
        <mesh filename="package:///meshes/non_printed/60_kg_servo.stl" scale="0.001 0.001 0.001"/>
      </geometry>
    </collision>
  </link>
  <link name="first_servo_mount">
    <visual>
      <geometry>
        <mesh filename="package:///meshes/frame/servo_mount_60kg.stl" scale="0.001 0.001 0.001"/>
      </geometry>
      <material name="skootr_blue"/>
    </visual>
    <collision>
      <geometry>
        <mesh filename="package:///meshes/frame/servo_mount_60kg.stl" scale="0.001 0.001 0.001"/>
      </geometry>
    </collision>
  </link>
  <link name="second_servo_mount">
    <visual>
      <geometry>
        <mesh filename="package:///meshes/frame/servo_mount_60kg.stl" scale="0.001 0.001 0.001"/>
      </geometry>
      <material name="skootr_blue"/>
    </visual>
    <collision>
      <geometry>
        <mesh filename="package:///meshes/frame/servo_mount_60kg.stl" scale="0.001 0.001 0.001"/>
      </geometry>
    </collision>
  </link>
  <link name="third_servo_mount">
    <visual>
      <geometry>
        <mesh filename="package:///meshes/frame/servo_mount_60kg.stl" scale="0.001 0.001 0.001"/>
      </geometry>
      <material name="skootr_blue"/>
    </visual>
    <collision>
      <geometry>
        <mesh filename="package:///meshes/frame/servo_mount_60kg.stl" scale="0.001 0.001 0.001"/>
      </geometry>
    </collision>
  </link>
  <joint name="first_servo_to_slot" type="fixed">
    <origin rpy="0.0 0.0 1.5707963267948966" xyz="0.0 0.0 0.0278"/>
    <parent link="first_servo_mount"/>
    <child link="first_servo"/>
  </joint>
  <joint name="second_servo_to_slot" type="fixed">
    <origin rpy="0.0 0.0 1.5707963267948966" xyz="0.0 0.0 0.0278"/>
    <parent link="second_servo_mount"/>
    <child link="second_servo"/>
  </joint>
  <joint name="third_servo_to_slot" type="fixed">
    <origin rpy="0.0 0.0 1.5707963267948966" xyz="0.0 0.0 0.0278"/>
    <parent link="third_servo_mount"/>
    <child link="third_servo"/>
  </joint>
  <joint name="first_servo_to_hub" type="fixed">
    <origin rpy="0.0 1.5707963267948966 -1.5707963267948966" xyz="0.078 0.014 0.026"/>
    <parent link="servo_hub_bottom"/>
    <child link="first_servo_mount"/>
  </joint>
  <joint name="second_servo_to_hub" type="fixed">
    <origin rpy="0.0 1.5707963267948966 2.617993877991494" xyz="-0.027 -0.0745 0.026"/>
    <parent link="servo_hub_bottom"/>
    <child link="second_servo_mount"/>
  </joint>
  <joint name="third_servo_to_hub" type="fixed">
    <origin rpy="0.0 1.5707963267948966 0.5235987755982989" xyz="-0.051 0.0605 0.026"/>
    <parent link="servo_hub_bottom"/>
    <child link="third_servo_mount"/>
  </joint>
  <!-- connecting with legs, adding horn -->
  <link name="first_servo_horn">
    <visual>
      <geometry>
        <mesh filename="package:///meshes/non_printed/18T_servo_horn.stl" scale="0.001 0.001 0.001"/>
      </geometry>
      <material name="horn_purple"/>
    </visual>
    <collision>
      <geometry>
        <mesh filename="package:///meshes/non_printed/18T_servo_horn.stl" scale="0.001 0.001 0.001"/>
      </geometry>
    </collision>
  </link>
  <link name="second_servo_horn">
    <visual>
      <geometry>
        <mesh filename="package:///meshes/non_printed/18T_servo_horn.stl" scale="0.001 0.001 0.001"/>
      </geometry>
      <material name="horn_purple"/>
    </visual>
    <collision>
      <geometry>
        <mesh filename="package:///meshes/non_printed/18T_servo_horn.stl" scale="0.001 0.001 0.001"/>
      </geometry>
    </collision>
  </link>
  <link name="third_servo_horn">
    <visual>
      <geometry>
        <mesh filename="package:///meshes/non_printed/18T_servo_horn.stl" scale="0.001 0.001 0.001"/>
      </geometry>
      <material name="horn_purple"/>
    </visual>
    <collision>
      <geometry>
        <mesh filename="package:///meshes/non_printed/18T_servo_horn.stl" scale="0.001 0.001 0.001"/>
      </geometry>
    </collision>
  </link>
  <!-- <joint name="first_servo_to_horn" type="fixed">
      <origin xyz="0.019 -0.0 0.0245" rpy="0 0 ${pi/2 + 0.872664626}"/>
      <parent link="first_servo"/>
      <child link="first_servo_horn"/>
    </joint> -->
  <joint name="first_servo_to_horn" type="revolute">
    <origin rpy="0 0 2.4434609527948967" xyz="0.019 -0.0 0.0245"/>
    <axis xyz="0 0 -1"/>
    <parent link="first_servo"/>
    <child link="first_servo_horn"/>
    <limit effort="1" lower="-0" upper="1.187" velocity="1"/>
  </joint>
  <joint name="second_servo_to_horn" type="revolute">
    <origin rpy="0 0 2.4434609527948967" xyz="0.019 -0.0 0.0245"/>
    <axis xyz="0 0 -1"/>
    <parent link="second_servo"/>
    <child link="second_servo_horn"/>
    <limit effort="1" lower="-0" upper="1.187" velocity="1"/>
  </joint>
  <joint name="third_servo_to_horn" type="revolute">
    <origin rpy="0 0 2.4434609527948967" xyz="0.019 -0.0 0.0245"/>
    <axis xyz="0 0 -1"/>
    <parent link="third_servo"/>
    <child link="third_servo_horn"/>
    <limit effort="1" lower="-0" upper="1.187" velocity="1"/>
  </joint>
  <!-- electronics -->
  <link name="electronics_platform">
    <visual>
      <geometry>
        <mesh filename="package:///meshes/frame/electronics_platform.stl" scale="0.001 0.001 0.001"/>
      </geometry>
      <material name="skootr_blue"/>
    </visual>
    <collision>
      <geometry>
        <mesh filename="package:///meshes/frame/electronics_platform.stl" scale="0.001 0.001 0.001"/>
      </geometry>
    </collision>
  </link>
  <link name="lid">
    <visual>
      <geometry>
        <mesh filename="package:///meshes/frame/lid.stl" scale="0.001 0.001 0.001"/>
      </geometry>
      <material name="skootr_blue"/>
    </visual>
    <collision>
      <geometry>
        <mesh filename="package:///meshes/frame/lid.stl" scale="0.001 0.001 0.001"/>
      </geometry>
    </collision>
  </link>
  <joint name="triconstraint_hub_to_electronics_platform" type="fixed">
    <origin rpy="0.0 3.141592653589793 0.5235987755982988" xyz="0.0 -0.0 0.156"/>
    <parent link="triconstraint_hub"/>
    <child link="electronics_platform"/>
  </joint>
  <joint name="electronics_platform_to_lid" type="fixed">
    <origin rpy="0.0 0.0 0.0" xyz="0.0 -0.0 -0.05"/>
    <parent link="electronics_platform"/>
    <child link="lid"/>
  </joint>
  <!-- link2 -->
  <link name="leg1_link2_p1">
    <visual>
      <geometry>
        <mesh filename="package:///meshes/legs/link2p1.stl" scale="0.001 0.001 0.001"/>
      </geometry>
      <material name="leg1_link2_p1_blue">
        <color rgba="0.231 0.380 0.706 1.0"/>
      </material>
    </visual>
    <collision>
      <geometry>
        <mesh filename="package:///meshes/legs/link2p1.stl" scale="0.001 0.001 0.001"/>
      </geometry>
    </collision>
  </link>
  <link name="leg1_link2_p2">
    <visual>
      <geometry>
        <mesh filename="package:///meshes/legs/link2p2.stl" scale="0.001 0.001 0.001"/>
      </geometry>
      <material name="leg1_link2_p2_yellow">
        <color rgba="0.980 0.714 0.004 1.0"/>
      </material>
    </visual>
    <collision>
      <geometry>
        <mesh filename="package:///meshes/legs/link2p2.stl" scale="0.001 0.001 0.001"/>
      </geometry>
    </collision>
  </link>
  <link name="leg1_link2_p3">
    <visual>
      <geometry>
        <mesh filename="package:///meshes/legs/link2p3.stl" scale="0.001 0.001 0.001"/>
      </geometry>
      <material name="leg1_link2_p3_yellow">
        <color rgba="0.980 0.714 0.004 1.0"/>
      </material>
    </visual>
    <collision>
      <geometry>
        <mesh filename="package:///meshes/legs/link2p3.stl" scale="0.001 0.001 0.001"/>
      </geometry>
    </collision>
  </link>
  <joint name="leg1_link2_p1_to_p2" type="fixed">
    <origin rpy="0.0 0.0 0.0" xyz="0.0 0.0 0.0"/>
    <parent link="leg1_link2_p1"/>
    <child link="leg1_link2_p2"/>
  </joint>
  <joint name="leg1_link2_p2_to_p3" type="fixed">
    <origin rpy="0.0 1.5707963267948966 0.0" xyz="-0.220 0.0 0.006"/>
    <parent link="leg1_link2_p2"/>
    <child link="leg1_link2_p3"/>
  </joint>
  <link name="leg1_pusher_servo_mount">
    <visual>
      <geometry>
        <mesh filename="package:///meshes/legs/pusher_servo_mount.stl" scale="0.001 0.001 0.001"/>
      </geometry>
      <material name="leg1_pusher_servo_mount_yellow">
        <color rgba="0.980 0.714 0.004 1.0"/>
      </material>
    </visual>
    <collision>
      <geometry>
        <mesh filename="package:///meshes/legs/pusher_servo_mount.stl" scale="0.001 0.001 0.001"/>
      </geometry>
    </collision>
  </link>
  <joint name="leg1_pusher_servo_mount_to_link2" type="fixed">
    <origin rpy="0.0 0.0 1.5707963267948966" xyz="-0.147 0.0 0.012"/>
    <parent link="leg1_link2_p2"/>
    <child link="leg1_pusher_servo_mount"/>
  </joint>
  <link name="leg1_pusher_servo">
    <visual>
      <geometry>
        <mesh filename="package:///meshes/non_printed/pusher_servo.stl" scale="0.001 0.001 0.001"/>
      </geometry>
      <material name="leg1_pusher_servo_blue">
        <color rgba="0.043 0.216 0.404 1.0"/>
      </material>
    </visual>
    <collision>
      <geometry>
        <mesh filename="package:///meshes/non_printed/pusher_servo.stl" scale="0.001 0.001 0.001"/>
      </geometry>
    </collision>
  </link>
  <joint name="leg1_pusher_servo_to_mount" type="fixed">
    <origin rpy="0.0 0.0 -1.5707963267948966" xyz="0.01 -0.0 0.0096"/>
    <parent link="leg1_pusher_servo_mount"/>
    <child link="leg1_pusher_servo"/>
  </joint>
  <!-- link1 -->
  <link name="servo_leg1_link1">
    <visual>
      <geometry>
        <mesh filename="package:///meshes/non_printed/60_kg_servo.stl" scale="0.001 0.001 0.001"/>
      </geometry>
      <material name="servo_leg1_link1_blue">
        <color rgba="0.043 0.216 0.404 1.0"/>
      </material>
    </visual>
    <collision>
      <geometry>
        <mesh filename="package:///meshes/non_printed/60_kg_servo.stl" scale="0.001 0.001 0.001"/>
      </geometry>
    </collision>
  </link>
  <link name="servo_mount_leg1_link1">
    <visual>
      <geometry>
        <mesh filename="package:///meshes/legs/servo_mount_slotted_60kg.stl" scale="0.001 0.001 0.001"/>
      </geometry>
      <material name="servo_mount_leg1_link1_blue">
        <color rgba="0.231 0.380 0.706 1.0"/>
      </material>
    </visual>
    <collision>
      <geometry>
        <mesh filename="package:///meshes/legs/servo_mount_slotted_60kg.stl" scale="0.001 0.001 0.001"/>
      </geometry>
    </collision>
  </link>
  <joint name="leg1_link1_servo_to_mount" type="fixed">
    <origin rpy="0.0 0.0 1.5707963267948966" xyz="0.0 0.0 0.0278"/>
    <parent link="servo_mount_leg1_link1"/>
    <child link="servo_leg1_link1"/>
  </joint>
  <link name="leg1_link1">
    <visual>
      <geometry>
        <mesh filename="package:///meshes/legs/link1.stl" scale="0.001 0.001 0.001"/>
      </geometry>
      <material name="leg1_link1_blue">
        <color rgba="0.231 0.380 0.706 1.0"/>
      </material>
    </visual>
    <collision>
      <geometry>
        <mesh filename="package:///meshes/legs/link1.stl" scale="0.001 0.001 0.001"/>
      </geometry>
    </collision>
  </link>
  <joint name="leg1_link1_to_servo" type="fixed">
    <origin rpy="0.0 1.5707963267948966 1.5707963267948966" xyz="-0.123 -0.031 0.0065"/>
    <parent link="leg1_link1"/>
    <child link="servo_mount_leg1_link1"/>
  </joint>
  <!-- horn -->
  <link name="leg1_horn_sleeve">
    <visual>
      <geometry>
        <mesh filename="package:///meshes/legs/horn_sleeve.stl" scale="0.001 0.001 0.001"/>
      </geometry>
      <material name="leg1_horn_sleeve_yellow">
        <color rgba="0.980 0.714 0.004 1.0"/>
      </material>
    </visual>
    <collision>
      <geometry>
        <mesh filename="package:///meshes/legs/horn_sleeve.stl" scale="0.001 0.001 0.001"/>
      </geometry>
    </collision>
  </link>
  <link name="leg1_actuator_arm">
    <visual>
      <geometry>
        <mesh filename="package:///meshes/legs/actuator_arm.stl" scale="0.001 0.001 0.001"/>
      </geometry>
      <material name="leg1_actuator_arm_yellow">
        <color rgba="0.980 0.714 0.004 1.0"/>
      </material>
    </visual>
    <collision>
      <geometry>
        <mesh filename="package:///meshes/legs/actuator_arm.stl" scale="0.001 0.001 0.001"/>
      </geometry>
    </collision>
  </link>
  <link name="leg1_pusher_servo_horn">
    <visual>
      <geometry>
        <mesh filename="package:///meshes/non_printed/pusher_servo_horn.stl" scale="0.001 0.001 0.001"/>
      </geometry>
      <material name="leg1_pusher_servo_horn_black">
        <color rgba="0.0 0.0 0.0 1.0"/>
      </material>
    </visual>
    <collision>
      <geometry>
        <mesh filename="package:///meshes/non_printed/pusher_servo_horn.stl" scale="0.001 0.001 0.001"/>
      </geometry>
    </collision>
  </link>
  <link name="leg1_sliding_cylinder">
    <visual>
      <geometry>
        <mesh filename="package:///meshes/legs/sliding_cylinder.stl" scale="0.001 0.001 0.001"/>
      </geometry>
      <material name="leg1_sliding_cylinder_blue">
        <color rgba="0.231 0.380 0.706 1.0"/>
      </material>
    </visual>
    <collision>
      <geometry>
        <mesh filename="package:///meshes/legs/sliding_cylinder.stl" scale="0.001 0.001 0.001"/>
      </geometry>
    </collision>
  </link>
  <link name="leg1_wheels">
    <visual>
      <geometry>
        <mesh filename="package:///meshes/non_printed/metal_bearing.stl" scale="0.001 0.001 0.001"/>
      </geometry>
      <material name="leg1_wheels_silver">
        <color rgba="0.9176 0.9176 0.9176 1.0"/>
      </material>
    </visual>
    <collision>
      <geometry>
        <mesh filename="package:///meshes/non_printed/metal_bearing.stl" scale="0.001 0.001 0.001"/>
      </geometry>
    </collision>
  </link>
  <joint name="leg1_servo_to_horn" type="revolute">
    <origin rpy="0.0 0.0 1.5707963267948966" xyz="0.0075 -0.01 0.02"/>
    <parent link="leg1_pusher_servo"/>
    <child link="leg1_pusher_servo_horn"/>
    <axis xyz="0.0 0.0 1.0"/>
    <limit effort="50.0" lower="-1.5707963267948966" upper="1.5707963267948966" velocity="1.0"/>
  </joint>
  <joint name="leg1_servo_horn_to_sleeve" type="fixed">
    <origin rpy="3.141592653589793 0.0 1.5707963267948966" xyz="-0.0 0.0 0.005"/>
    <parent link="leg1_pusher_servo_horn"/>
    <child link="leg1_horn_sleeve"/>
  </joint>
  <joint name="leg1_sleeve_to_arm" type="continuous">
    <origin rpy="-1.5707963267948966 0.0 1.5707963267948966" xyz="0.0212344 -0.0 0.0039878"/>
    <parent link="leg1_horn_sleeve"/>
    <child link="leg1_actuator_arm"/>
    <axis xyz="0.0 1.0 0.0"/>
  </joint>
  <joint name="leg1_cylinder_to_arm" type="continuous">
    <origin rpy="1.5707963267948966 0.0 0.0" xyz="-0.0 -0.0027 -0.046"/>
    <parent link="leg1_actuator_arm"/>
    <child link="leg1_sliding_cylinder"/>
    <axis xyz="0.0 0.0 1.0"/>
  </joint>
  <joint name="leg1_cylinder_to_wheels" type="fixed">
    <origin rpy="0 0.0 3.141592653589793" xyz="-0.0 -0.0405 -0.0"/>
    <parent link="leg1_sliding_cylinder"/>
    <child link="leg1_wheels"/>
  </joint>
  <!-- joining link1 and link2 -->
  <link name="leg1_servo_horn">
    <visual>
      <geometry>
        <mesh filename="package:///meshes/non_printed/18T_servo_horn.stl" scale="0.001 0.001 0.001"/>
      </geometry>
      <material name="leg1_servo_horn_purple">
        <color rgba="0.490 0.086 0.557 1.0"/>
      </material>
    </visual>
    <collision>
      <geometry>
        <mesh filename="package:///meshes/non_printed/18T_servo_horn.stl" scale="0.001 0.001 0.001"/>
      </geometry>
    </collision>
  </link>
  <joint name="leg1_link1_to_joint" type="revolute">
    <origin rpy="0 0 1.2915436467948966" xyz="0.019 -0.0 0.0245"/>
    <parent link="servo_leg1_link1"/>
    <child link="leg1_servo_horn"/>
    <axis xyz="0 0 1"/>
    <limit effort="1" lower="-2.356" upper="2.356" velocity="1"/>
  </joint>
  <joint name="leg1_joint_to_link2" type="fixed">
    <origin rpy="1.5707963267948966 3.141592653589793 -1.5707963267948966" xyz="0.005 0.005 -0.028"/>
    <parent link="leg1_servo_horn"/>
    <child link="leg1_link2_p1"/>
  </joint>
  <!-- joining to the base -->
  <joint name="leg1_link1_to_frame" type="fixed">
    <origin rpy="1.5707963267948966 3.141592653589793 -1.5707963267948966" xyz="0.005 0.005 -0.028"/>
    <parent link="first_servo_horn"/>
    <child link="leg1_link1"/>
  </joint>
  <!-- link2 -->
  <link name="leg2_link2_p1">
    <visual>
      <geometry>
        <mesh filename="package:///meshes/legs/link2p1.stl" scale="0.001 0.001 0.001"/>
      </geometry>
      <material name="leg2_link2_p1_blue">
        <color rgba="0.231 0.380 0.706 1.0"/>
      </material>
    </visual>
    <collision>
      <geometry>
        <mesh filename="package:///meshes/legs/link2p1.stl" scale="0.001 0.001 0.001"/>
      </geometry>
    </collision>
  </link>
  <link name="leg2_link2_p2">
    <visual>
      <geometry>
        <mesh filename="package:///meshes/legs/link2p2.stl" scale="0.001 0.001 0.001"/>
      </geometry>
      <material name="leg2_link2_p2_yellow">
        <color rgba="0.980 0.714 0.004 1.0"/>
      </material>
    </visual>
    <collision>
      <geometry>
        <mesh filename="package:///meshes/legs/link2p2.stl" scale="0.001 0.001 0.001"/>
      </geometry>
    </collision>
  </link>
  <link name="leg2_link2_p3">
    <visual>
      <geometry>
        <mesh filename="package:///meshes/legs/link2p3.stl" scale="0.001 0.001 0.001"/>
      </geometry>
      <material name="leg2_link2_p3_yellow">
        <color rgba="0.980 0.714 0.004 1.0"/>
      </material>
    </visual>
    <collision>
      <geometry>
        <mesh filename="package:///meshes/legs/link2p3.stl" scale="0.001 0.001 0.001"/>
      </geometry>
    </collision>
  </link>
  <joint name="leg2_link2_p1_to_p2" type="fixed">
    <origin rpy="0.0 0.0 0.0" xyz="0.0 0.0 0.0"/>
    <parent link="leg2_link2_p1"/>
    <child link="leg2_link2_p2"/>
  </joint>
  <joint name="leg2_link2_p2_to_p3" type="fixed">
    <origin rpy="0.0 1.5707963267948966 0.0" xyz="-0.220 0.0 0.006"/>
    <parent link="leg2_link2_p2"/>
    <child link="leg2_link2_p3"/>
  </joint>
  <link name="leg2_pusher_servo_mount">
    <visual>
      <geometry>
        <mesh filename="package:///meshes/legs/pusher_servo_mount.stl" scale="0.001 0.001 0.001"/>
      </geometry>
      <material name="leg2_pusher_servo_mount_yellow">
        <color rgba="0.980 0.714 0.004 1.0"/>
      </material>
    </visual>
    <collision>
      <geometry>
        <mesh filename="package:///meshes/legs/pusher_servo_mount.stl" scale="0.001 0.001 0.001"/>
      </geometry>
    </collision>
  </link>
  <joint name="leg2_pusher_servo_mount_to_link2" type="fixed">
    <origin rpy="0.0 0.0 1.5707963267948966" xyz="-0.147 0.0 0.012"/>
    <parent link="leg2_link2_p2"/>
    <child link="leg2_pusher_servo_mount"/>
  </joint>
  <link name="leg2_pusher_servo">
    <visual>
      <geometry>
        <mesh filename="package:///meshes/non_printed/pusher_servo.stl" scale="0.001 0.001 0.001"/>
      </geometry>
      <material name="leg2_pusher_servo_blue">
        <color rgba="0.043 0.216 0.404 1.0"/>
      </material>
    </visual>
    <collision>
      <geometry>
        <mesh filename="package:///meshes/non_printed/pusher_servo.stl" scale="0.001 0.001 0.001"/>
      </geometry>
    </collision>
  </link>
  <joint name="leg2_pusher_servo_to_mount" type="fixed">
    <origin rpy="0.0 0.0 -1.5707963267948966" xyz="0.01 -0.0 0.0096"/>
    <parent link="leg2_pusher_servo_mount"/>
    <child link="leg2_pusher_servo"/>
  </joint>
  <!-- link1 -->
  <link name="servo_leg2_link1">
    <visual>
      <geometry>
        <mesh filename="package:///meshes/non_printed/60_kg_servo.stl" scale="0.001 0.001 0.001"/>
      </geometry>
      <material name="servo_leg2_link1_blue">
        <color rgba="0.043 0.216 0.404 1.0"/>
      </material>
    </visual>
    <collision>
      <geometry>
        <mesh filename="package:///meshes/non_printed/60_kg_servo.stl" scale="0.001 0.001 0.001"/>
      </geometry>
    </collision>
  </link>
  <link name="servo_mount_leg2_link1">
    <visual>
      <geometry>
        <mesh filename="package:///meshes/legs/servo_mount_slotted_60kg.stl" scale="0.001 0.001 0.001"/>
      </geometry>
      <material name="servo_mount_leg2_link1_blue">
        <color rgba="0.231 0.380 0.706 1.0"/>
      </material>
    </visual>
    <collision>
      <geometry>
        <mesh filename="package:///meshes/legs/servo_mount_slotted_60kg.stl" scale="0.001 0.001 0.001"/>
      </geometry>
    </collision>
  </link>
  <joint name="leg2_link1_servo_to_mount" type="fixed">
    <origin rpy="0.0 0.0 1.5707963267948966" xyz="0.0 0.0 0.0278"/>
    <parent link="servo_mount_leg2_link1"/>
    <child link="servo_leg2_link1"/>
  </joint>
  <link name="leg2_link1">
    <visual>
      <geometry>
        <mesh filename="package:///meshes/legs/link1.stl" scale="0.001 0.001 0.001"/>
      </geometry>
      <material name="leg2_link1_blue">
        <color rgba="0.231 0.380 0.706 1.0"/>
      </material>
    </visual>
    <collision>
      <geometry>
        <mesh filename="package:///meshes/legs/link1.stl" scale="0.001 0.001 0.001"/>
      </geometry>
    </collision>
  </link>
  <joint name="leg2_link1_to_servo" type="fixed">
    <origin rpy="0.0 1.5707963267948966 1.5707963267948966" xyz="-0.123 -0.031 0.0065"/>
    <parent link="leg2_link1"/>
    <child link="servo_mount_leg2_link1"/>
  </joint>
  <!-- horn -->
  <link name="leg2_horn_sleeve">
    <visual>
      <geometry>
        <mesh filename="package:///meshes/legs/horn_sleeve.stl" scale="0.001 0.001 0.001"/>
      </geometry>
      <material name="leg2_horn_sleeve_yellow">
        <color rgba="0.980 0.714 0.004 1.0"/>
      </material>
    </visual>
    <collision>
      <geometry>
        <mesh filename="package:///meshes/legs/horn_sleeve.stl" scale="0.001 0.001 0.001"/>
      </geometry>
    </collision>
  </link>
  <link name="leg2_actuator_arm">
    <visual>
      <geometry>
        <mesh filename="package:///meshes/legs/actuator_arm.stl" scale="0.001 0.001 0.001"/>
      </geometry>
      <material name="leg2_actuator_arm_yellow">
        <color rgba="0.980 0.714 0.004 1.0"/>
      </material>
    </visual>
    <collision>
      <geometry>
        <mesh filename="package:///meshes/legs/actuator_arm.stl" scale="0.001 0.001 0.001"/>
      </geometry>
    </collision>
  </link>
  <link name="leg2_pusher_servo_horn">
    <visual>
      <geometry>
        <mesh filename="package:///meshes/non_printed/pusher_servo_horn.stl" scale="0.001 0.001 0.001"/>
      </geometry>
      <material name="leg2_pusher_servo_horn_black">
        <color rgba="0.0 0.0 0.0 1.0"/>
      </material>
    </visual>
    <collision>
      <geometry>
        <mesh filename="package:///meshes/non_printed/pusher_servo_horn.stl" scale="0.001 0.001 0.001"/>
      </geometry>
    </collision>
  </link>
  <link name="leg2_sliding_cylinder">
    <visual>
      <geometry>
        <mesh filename="package:///meshes/legs/sliding_cylinder.stl" scale="0.001 0.001 0.001"/>
      </geometry>
      <material name="leg2_sliding_cylinder_blue">
        <color rgba="0.231 0.380 0.706 1.0"/>
      </material>
    </visual>
    <collision>
      <geometry>
        <mesh filename="package:///meshes/legs/sliding_cylinder.stl" scale="0.001 0.001 0.001"/>
      </geometry>
    </collision>
  </link>
  <link name="leg2_wheels">
    <visual>
      <geometry>
        <mesh filename="package:///meshes/non_printed/metal_bearing.stl" scale="0.001 0.001 0.001"/>
      </geometry>
      <material name="leg2_wheels_silver">
        <color rgba="0.9176 0.9176 0.9176 1.0"/>
      </material>
    </visual>
    <collision>
      <geometry>
        <mesh filename="package:///meshes/non_printed/metal_bearing.stl" scale="0.001 0.001 0.001"/>
      </geometry>
    </collision>
  </link>
  <joint name="leg2_servo_to_horn" type="revolute">
    <origin rpy="0.0 0.0 1.5707963267948966" xyz="0.0075 -0.01 0.02"/>
    <parent link="leg2_pusher_servo"/>
    <child link="leg2_pusher_servo_horn"/>
    <axis xyz="0.0 0.0 1.0"/>
    <limit effort="50.0" lower="-1.5707963267948966" upper="1.5707963267948966" velocity="1.0"/>
  </joint>
  <joint name="leg2_servo_horn_to_sleeve" type="fixed">
    <origin rpy="3.141592653589793 0.0 1.5707963267948966" xyz="-0.0 0.0 0.005"/>
    <parent link="leg2_pusher_servo_horn"/>
    <child link="leg2_horn_sleeve"/>
  </joint>
  <joint name="leg2_sleeve_to_arm" type="continuous">
    <origin rpy="-1.5707963267948966 0.0 1.5707963267948966" xyz="0.0212344 -0.0 0.0039878"/>
    <parent link="leg2_horn_sleeve"/>
    <child link="leg2_actuator_arm"/>
    <axis xyz="0.0 1.0 0.0"/>
  </joint>
  <joint name="leg2_cylinder_to_arm" type="continuous">
    <origin rpy="1.5707963267948966 0.0 0.0" xyz="-0.0 -0.0027 -0.046"/>
    <parent link="leg2_actuator_arm"/>
    <child link="leg2_sliding_cylinder"/>
    <axis xyz="0.0 0.0 1.0"/>
  </joint>
  <joint name="leg2_cylinder_to_wheels" type="fixed">
    <origin rpy="0 0.0 3.141592653589793" xyz="-0.0 -0.0405 -0.0"/>
    <parent link="leg2_sliding_cylinder"/>
    <child link="leg2_wheels"/>
  </joint>
  <!-- joining link1 and link2 -->
  <link name="leg2_servo_horn">
    <visual>
      <geometry>
        <mesh filename="package:///meshes/non_printed/18T_servo_horn.stl" scale="0.001 0.001 0.001"/>
      </geometry>
      <material name="leg2_servo_horn_purple">
        <color rgba="0.490 0.086 0.557 1.0"/>
      </material>
    </visual>
    <collision>
      <geometry>
        <mesh filename="package:///meshes/non_printed/18T_servo_horn.stl" scale="0.001 0.001 0.001"/>
      </geometry>
    </collision>
  </link>
  <joint name="leg2_link1_to_joint" type="revolute">
    <origin rpy="0 0 1.2915436467948966" xyz="0.019 -0.0 0.0245"/>
    <parent link="servo_leg2_link1"/>
    <child link="leg2_servo_horn"/>
    <axis xyz="0 0 1"/>
    <limit effort="1" lower="-2.356" upper="2.356" velocity="1"/>
  </joint>
  <joint name="leg2_joint_to_link2" type="fixed">
    <origin rpy="1.5707963267948966 3.141592653589793 -1.5707963267948966" xyz="0.005 0.005 -0.028"/>
    <parent link="leg2_servo_horn"/>
    <child link="leg2_link2_p1"/>
  </joint>
  <!-- joining to the base -->
  <joint name="leg2_link1_to_frame" type="fixed">
    <origin rpy="1.5707963267948966 3.141592653589793 -1.5707963267948966" xyz="0.005 0.005 -0.028"/>
    <parent link="second_servo_horn"/>
    <child link="leg2_link1"/>
  </joint>
  <!-- link2 -->
  <link name="leg3_link2_p1">
    <visual>
      <geometry>
        <mesh filename="package:///meshes/legs/link2p1.stl" scale="0.001 0.001 0.001"/>
      </geometry>
      <material name="leg3_link2_p1_blue">
        <color rgba="0.231 0.380 0.706 1.0"/>
      </material>
    </visual>
    <collision>
      <geometry>
        <mesh filename="package:///meshes/legs/link2p1.stl" scale="0.001 0.001 0.001"/>
      </geometry>
    </collision>
  </link>
  <link name="leg3_link2_p2">
    <visual>
      <geometry>
        <mesh filename="package:///meshes/legs/link2p2.stl" scale="0.001 0.001 0.001"/>
      </geometry>
      <material name="leg3_link2_p2_yellow">
        <color rgba="0.980 0.714 0.004 1.0"/>
      </material>
    </visual>
    <collision>
      <geometry>
        <mesh filename="package:///meshes/legs/link2p2.stl" scale="0.001 0.001 0.001"/>
      </geometry>
    </collision>
  </link>
  <link name="leg3_link2_p3">
    <visual>
      <geometry>
        <mesh filename="package:///meshes/legs/link2p3.stl" scale="0.001 0.001 0.001"/>
      </geometry>
      <material name="leg3_link2_p3_yellow">
        <color rgba="0.980 0.714 0.004 1.0"/>
      </material>
    </visual>
    <collision>
      <geometry>
        <mesh filename="package:///meshes/legs/link2p3.stl" scale="0.001 0.001 0.001"/>
      </geometry>
    </collision>
  </link>
  <joint name="leg3_link2_p1_to_p2" type="fixed">
    <origin rpy="0.0 0.0 0.0" xyz="0.0 0.0 0.0"/>
    <parent link="leg3_link2_p1"/>
    <child link="leg3_link2_p2"/>
  </joint>
  <joint name="leg3_link2_p2_to_p3" type="fixed">
    <origin rpy="0.0 1.5707963267948966 0.0" xyz="-0.220 0.0 0.006"/>
    <parent link="leg3_link2_p2"/>
    <child link="leg3_link2_p3"/>
  </joint>
  <link name="leg3_pusher_servo_mount">
    <visual>
      <geometry>
        <mesh filename="package:///meshes/legs/pusher_servo_mount.stl" scale="0.001 0.001 0.001"/>
      </geometry>
      <material name="leg3_pusher_servo_mount_yellow">
        <color rgba="0.980 0.714 0.004 1.0"/>
      </material>
    </visual>
    <collision>
      <geometry>
        <mesh filename="package:///meshes/legs/pusher_servo_mount.stl" scale="0.001 0.001 0.001"/>
      </geometry>
    </collision>
  </link>
  <joint name="leg3_pusher_servo_mount_to_link2" type="fixed">
    <origin rpy="0.0 0.0 1.5707963267948966" xyz="-0.147 0.0 0.012"/>
    <parent link="leg3_link2_p2"/>
    <child link="leg3_pusher_servo_mount"/>
  </joint>
  <link name="leg3_pusher_servo">
    <visual>
      <geometry>
        <mesh filename="package:///meshes/non_printed/pusher_servo.stl" scale="0.001 0.001 0.001"/>
      </geometry>
      <material name="leg3_pusher_servo_blue">
        <color rgba="0.043 0.216 0.404 1.0"/>
      </material>
    </visual>
    <collision>
      <geometry>
        <mesh filename="package:///meshes/non_printed/pusher_servo.stl" scale="0.001 0.001 0.001"/>
      </geometry>
    </collision>
  </link>
  <joint name="leg3_pusher_servo_to_mount" type="fixed">
    <origin rpy="0.0 0.0 -1.5707963267948966" xyz="0.01 -0.0 0.0096"/>
    <parent link="leg3_pusher_servo_mount"/>
    <child link="leg3_pusher_servo"/>
  </joint>
  <!-- link1 -->
  <link name="servo_leg3_link1">
    <visual>
      <geometry>
        <mesh filename="package:///meshes/non_printed/60_kg_servo.stl" scale="0.001 0.001 0.001"/>
      </geometry>
      <material name="servo_leg3_link1_blue">
        <color rgba="0.043 0.216 0.404 1.0"/>
      </material>
    </visual>
    <collision>
      <geometry>
        <mesh filename="package:///meshes/non_printed/60_kg_servo.stl" scale="0.001 0.001 0.001"/>
      </geometry>
    </collision>
  </link>
  <link name="servo_mount_leg3_link1">
    <visual>
      <geometry>
        <mesh filename="package:///meshes/legs/servo_mount_slotted_60kg.stl" scale="0.001 0.001 0.001"/>
      </geometry>
      <material name="servo_mount_leg3_link1_blue">
        <color rgba="0.231 0.380 0.706 1.0"/>
      </material>
    </visual>
    <collision>
      <geometry>
        <mesh filename="package:///meshes/legs/servo_mount_slotted_60kg.stl" scale="0.001 0.001 0.001"/>
      </geometry>
    </collision>
  </link>
  <joint name="leg3_link1_servo_to_mount" type="fixed">
    <origin rpy="0.0 0.0 1.5707963267948966" xyz="0.0 0.0 0.0278"/>
    <parent link="servo_mount_leg3_link1"/>
    <child link="servo_leg3_link1"/>
  </joint>
  <link name="leg3_link1">
    <visual>
      <geometry>
        <mesh filename="package:///meshes/legs/link1.stl" scale="0.001 0.001 0.001"/>
      </geometry>
      <material name="leg3_link1_blue">
        <color rgba="0.231 0.380 0.706 1.0"/>
      </material>
    </visual>
    <collision>
      <geometry>
        <mesh filename="package:///meshes/legs/link1.stl" scale="0.001 0.001 0.001"/>
      </geometry>
    </collision>
  </link>
  <joint name="leg3_link1_to_servo" type="fixed">
    <origin rpy="0.0 1.5707963267948966 1.5707963267948966" xyz="-0.123 -0.031 0.0065"/>
    <parent link="leg3_link1"/>
    <child link="servo_mount_leg3_link1"/>
  </joint>
  <!-- horn -->
  <link name="leg3_horn_sleeve">
    <visual>
      <geometry>
        <mesh filename="package:///meshes/legs/horn_sleeve.stl" scale="0.001 0.001 0.001"/>
      </geometry>
      <material name="leg3_horn_sleeve_yellow">
        <color rgba="0.980 0.714 0.004 1.0"/>
      </material>
    </visual>
    <collision>
      <geometry>
        <mesh filename="package:///meshes/legs/horn_sleeve.stl" scale="0.001 0.001 0.001"/>
      </geometry>
    </collision>
  </link>
  <link name="leg3_actuator_arm">
    <visual>
      <geometry>
        <mesh filename="package:///meshes/legs/actuator_arm.stl" scale="0.001 0.001 0.001"/>
      </geometry>
      <material name="leg3_actuator_arm_yellow">
        <color rgba="0.980 0.714 0.004 1.0"/>
      </material>
    </visual>
    <collision>
      <geometry>
        <mesh filename="package:///meshes/legs/actuator_arm.stl" scale="0.001 0.001 0.001"/>
      </geometry>
    </collision>
  </link>
  <link name="leg3_pusher_servo_horn">
    <visual>
      <geometry>
        <mesh filename="package:///meshes/non_printed/pusher_servo_horn.stl" scale="0.001 0.001 0.001"/>
      </geometry>
      <material name="leg3_pusher_servo_horn_black">
        <color rgba="0.0 0.0 0.0 1.0"/>
      </material>
    </visual>
    <collision>
      <geometry>
        <mesh filename="package:///meshes/non_printed/pusher_servo_horn.stl" scale="0.001 0.001 0.001"/>
      </geometry>
    </collision>
  </link>
  <link name="leg3_sliding_cylinder">
    <visual>
      <geometry>
        <mesh filename="package:///meshes/legs/sliding_cylinder.stl" scale="0.001 0.001 0.001"/>
      </geometry>
      <material name="leg3_sliding_cylinder_blue">
        <color rgba="0.231 0.380 0.706 1.0"/>
      </material>
    </visual>
    <collision>
      <geometry>
        <mesh filename="package:///meshes/legs/sliding_cylinder.stl" scale="0.001 0.001 0.001"/>
      </geometry>
    </collision>
  </link>
  <link name="leg3_wheels">
    <visual>
      <geometry>
        <mesh filename="package:///meshes/non_printed/metal_bearing.stl" scale="0.001 0.001 0.001"/>
      </geometry>
      <material name="leg3_wheels_silver">
        <color rgba="0.9176 0.9176 0.9176 1.0"/>
      </material>
    </visual>
    <collision>
      <geometry>
        <mesh filename="package:///meshes/non_printed/metal_bearing.stl" scale="0.001 0.001 0.001"/>
      </geometry>
    </collision>
  </link>
  <joint name="leg3_servo_to_horn" type="revolute">
    <origin rpy="0.0 0.0 1.5707963267948966" xyz="0.0075 -0.01 0.02"/>
    <parent link="leg3_pusher_servo"/>
    <child link="leg3_pusher_servo_horn"/>
    <axis xyz="0.0 0.0 1.0"/>
    <limit effort="50.0" lower="-1.5707963267948966" upper="1.5707963267948966" velocity="1.0"/>
  </joint>
  <joint name="leg3_servo_horn_to_sleeve" type="fixed">
    <origin rpy="3.141592653589793 0.0 1.5707963267948966" xyz="-0.0 0.0 0.005"/>
    <parent link="leg3_pusher_servo_horn"/>
    <child link="leg3_horn_sleeve"/>
  </joint>
  <joint name="leg3_sleeve_to_arm" type="continuous">
    <origin rpy="-1.5707963267948966 0.0 1.5707963267948966" xyz="0.0212344 -0.0 0.0039878"/>
    <parent link="leg3_horn_sleeve"/>
    <child link="leg3_actuator_arm"/>
    <axis xyz="0.0 1.0 0.0"/>
  </joint>
  <joint name="leg3_cylinder_to_arm" type="continuous">
    <origin rpy="1.5707963267948966 0.0 0.0" xyz="-0.0 -0.0027 -0.046"/>
    <parent link="leg3_actuator_arm"/>
    <child link="leg3_sliding_cylinder"/>
    <axis xyz="0.0 0.0 1.0"/>
  </joint>
  <joint name="leg3_cylinder_to_wheels" type="fixed">
    <origin rpy="0 0.0 3.141592653589793" xyz="-0.0 -0.0405 -0.0"/>
    <parent link="leg3_sliding_cylinder"/>
    <child link="leg3_wheels"/>
  </joint>
  <!-- joining link1 and link2 -->
  <link name="leg3_servo_horn">
    <visual>
      <geometry>
        <mesh filename="package:///meshes/non_printed/18T_servo_horn.stl" scale="0.001 0.001 0.001"/>
      </geometry>
      <material name="leg3_servo_horn_purple">
        <color rgba="0.490 0.086 0.557 1.0"/>
      </material>
    </visual>
    <collision>
      <geometry>
        <mesh filename="package:///meshes/non_printed/18T_servo_horn.stl" scale="0.001 0.001 0.001"/>
      </geometry>
    </collision>
  </link>
  <joint name="leg3_link1_to_joint" type="revolute">
    <origin rpy="0 0 1.2915436467948966" xyz="0.019 -0.0 0.0245"/>
    <parent link="servo_leg3_link1"/>
    <child link="leg3_servo_horn"/>
    <axis xyz="0 0 1"/>
    <limit effort="1" lower="-2.356" upper="2.356" velocity="1"/>
  </joint>
  <joint name="leg3_joint_to_link2" type="fixed">
    <origin rpy="1.5707963267948966 3.141592653589793 -1.5707963267948966" xyz="0.005 0.005 -0.028"/>
    <parent link="leg3_servo_horn"/>
    <child link="leg3_link2_p1"/>
  </joint>
  <!-- joining to the base -->
  <joint name="leg3_link1_to_frame" type="fixed">
    <origin rpy="1.5707963267948966 3.141592653589793 -1.5707963267948966" xyz="0.005 0.005 -0.028"/>
    <parent link="third_servo_horn"/>
    <child link="leg3_link1"/>
  </joint>
</robot>
